Workbook
Name Вознаграждение: #REF!
Name Вознаграждение: #REF!
Name Вознаграждение: #REF!
Name ДатаФиниш: #REF!
Name ДатаФиниш: #REF!
Name ДатаФиниш: #REF!
Name договорная_сумма: #REF!
Name договорная_сумма: #REF!
Name договорная_сумма: #REF!
Name ДС: #REF!
Name ДС: #REF!
Name ДС: #REF!
Name ПВ: #REF!
Name ПВ: #REF!
Name ПВ: #REF!
Name ПВ: #REF!
Name регионы: #REF!
Name регионы: #REF!
Name регионы: #REF!
Name регионы: #REF!
Name Рынок: #REF!
Name Рынок: #REF!
Name Рынок: #REF!
Name Рынок: #REF!
Name состав: #REF!
Name состав: #REF!
Name состав: #REF!
Name состав: #REF!
Name Ставка: #REF!
Name Ставка: #REF!
Name Ставка: #REF!

Sheet для бигтандау
A1: Класс/Комнатность | B1: 1-комнатная | C1: 2-комнатная | D1: 3-комнатная | E1: 4-комнатная | F1: 5-комнатная
A2: стандарт | B2: 65573.77 | C2: 131147.54 | D2: 196721.31 | E2: 262295.08 | F2: 262295.08
A3: комфорт | B3: 65573.77 | C3: 131147.54 | D3: 196721.31 | E3: 262295.08 | F3: 262295.08
A4: комфорт+ | B4: 65573.77 | C4: 131147.54 | D4: 196721.31 | E4: 262295.08 | F4: 262295.08
A5: бизнес | B5: 98360.653 | C5: 163935 | D5: 229508.2 | E5: 295081 | F5: 295081
A6: бизнес+ | B6: 98360.653 | C6: 163935 | D6: 229508.2 | E6: 295081 | F6: 295081
A7: премиум ПД | B7: 98360.653 | C7: 163935 | D7: 229508.2 | E7: 295081 | F7: 295081
A10: Срок | B10: Ставка
A11: 12 | B11: 0.085
A12: 24 | B12: 0.085
A13: 36 | B13: 0.13
A14: 48 | B14: 0.13
A15: 60 | B15: 0.135
A18: Отделка | B18: Мин. ПВ
A19: Чистовая | B19: 0.2
A20: Черновая | B20: 0.3

Sheet Подборщик
A1: Город | B1: Объекты | C1: Тип помещений | F1: Остатки на 10.11.2025 | G1: Вид основания | H1: есть ФГЖС | I1: без доп залога | Y1: доп залог | AF1: готовое жилье
D2: Block_ID | E2: Block_ID тест | I2: Отбасы Банк (Женил), 50/50 | J2: Отбасы Банк Елорда Жастары | K2: FFB (Каскадная ипотека) готовое жилье | L2: FFB (Каскадная ипотека) ДДУ | M2: FFB (Цифровая ипотека) | N2: «Новая ипотека» 36/14 Отбасы Банк | O2: «Новая ипотека» 30/70 Отбасы Банк | P2: «Super ипотека» по БЦК | Q2: «Оңай ипотека (онлайн)» | R2: «Оңай ипотека (офлайн)» | S2: Halyk ипотека | T2: Наурыз/Наурыз жұмыскер Отбасы Банк | U2: KASPI паркинги/кладовые | V2: Рассрочка на паркинги/кладовые МФО FFC (онлайн) | W2: «BIG Tandau» от МФО BI FINANCE | X2: Бизнес Ипотека (на офисы от Алтын Банк) | Y2: Отбасы Банк (Женил под доп залог) 50/50 | Z2: «Новая ипотека» 36/14 Отбасы Банк | AA2: «Новая ипотека» 30/70 Отбасы Банк | AB2: Алтын Банк Стандарт БЦК (Залоговый кредит) | AC2: Зелёная ипотека Отбасы Банк | AD2: Женская ипотека «ҰМАЙ» Отбасы Банк | AE2: Аскери Баспана
A3: Астана | B3: Sezim Qala Orken - 1 | C3: жилые | F3: =VLOOKUP(B3,[3]Лист_1!$A:$E,5,0) -> 6 | G3: ДДУ | L3: да | M3: да | P3: да | Q3: да | S3: да | W3: да 36 | Y3: да, max 891 000 тенге за 1 кв.м. | AA3: да, max 891 000 тенге за 1 кв.м. | AD3: да | AE3: да
A4: Астана | B4: Jetisu. Aqsu - 5 | C4: жилые | F4: =VLOOKUP(B4,[3]Лист_1!$A:$E,5,0) -> 0 | G4: ПД | I4: да, max 600 000 тенге за 1 кв.м. | N4: да, max 600 000 тенге за 1 кв.м. | O4: да, max 600 000 тенге за 1 кв.м. | P4: да офлайн | R4: да | AD4: да | AE4: да | AF4: да
A5: Астана | B5: Jetisu Aqsu 6 | C5: жилые | F5: =VLOOKUP(B5,[3]Лист_1!$A:$E,5,0) -> 3 | G5: ДДУ | L5: да | M5: да | P5: да | Q5: да | S5: да | W5: да 36 | Y5: да, max 700 000 тенге за 1 кв.м. | AA5: да, max 700 000 тенге за 1 кв.м. | AB5: да | AD5: да
A6: Астана | B6: Jetisu Aqsu - 6 - ЧО | C6: жилые | F6: =VLOOKUP(B6,[3]Лист_1!$A:$E,5,0) -> 0 | G6: ДДУ | L6: да | M6: да | Q6: да | S6: да | W6: да 36 | Y6: да, max 700 000 тенге за 1 кв.м. | Z6: да, max 700 000 тенге за 1 кв.м. | AA6: да, max 700 000 тенге за 1 кв.м. | AB6: да | AD6: да
A7: Астана | B7: Jetisu Aspan A | C7: жилые | F7: =VLOOKUP(B7,[3]Лист_1!$A:$E,5,0) -> 30 | G7: ДДУ | L7: да | M7: да | P7: да | Q7: да | W7: да 36 | Y7: да | AD7: да
A8: Астана | B8: Jetisu Aspan A - ЧО | C8: жилые | F8: =VLOOKUP(B8,[3]Лист_1!$A:$E,5,0) -> 23 | G8: ДДУ | L8: да | M8: да | P8: да | Q8: да | W8: да 36 | Y8: да | AD8: да
A9: Астана | B9: Jetisu Kerbez - 2 | C9: жилые | F9: =VLOOKUP(B9,[3]Лист_1!$A:$E,5,0) -> 3 | G9: ДДУ | L9: да | M9: да | P9: да | Q9: да | S9: да | W9: да 36 | Y9: да, max 784 000 тенге за 1 кв.м. | Z9: да, max 700 000 тенге за 1 кв.м. | AA9: да, max 784 000 тенге за 1 кв.м. | AD9: да | AE9: да
A10: Астана | B10: Jetisu Kerbez - 2 - ЧО | C10: жилые | F10: =VLOOKUP(B10,[3]Лист_1!$A:$E,5,0) -> 1 | G10: ДДУ | L10: да | M10: да | P10: да | Q10: да | S10: да | W10: да 36 | Y10: да, max 784 000 тенге за 1 кв.м. | Z10: да, max 784 000 тенге за 1 кв.м. | AA10: да, max 784 000 тенге за 1 кв.м. | AD10: да | AE10: да
A11: Астана | B11: Jetisu Kerbez Comfort - 1 | C11: жилые | F11: =VLOOKUP(B11,[3]Лист_1!$A:$E,5,0) -> 68 | G11: ДДУ | I11: да, max 554 400 тенге за 1 кв.м. | L11: да | M11: да | P11: да | Q11: да | S11: да | T11: да | W11: да 36 | Y11: да | AA11: да, max 810 000 тенге за 1 кв.м. | AD11: да
A12: Астана | B12: Jetisu Kerbez Comfort - 1 - ЧО | C12: жилые | F12: =VLOOKUP(B12,[3]Лист_1!$A:$E,5,0) -> 32 | G12: ДДУ | L12: да | M12: да | P12: да | Q12: да | S12: да | W12: да 36 | Y12: да | AA12: да, max 810 000 тенге за 1 кв.м. | AD12: да
A13: Астана | B13: Jetisu Satti | C13: жилые | F13: =VLOOKUP(B13,[3]Лист_1!$A:$E,5,0) -> 56 | G13: ДДУ | L13: да | M13: да | P13: да | Q13: да | S13: да | W13: да 36 | Y13: да | AD13: да
A14: Астана | B14: AruPark - 1 | C14: жилые | F14: =VLOOKUP(B14,[3]Лист_1!$A:$E,5,0) -> 0 | G14: ПД | I14: да | R14: да | AD14: да | AF14: да
A15: Астана | B15: AruPark - 1 - ЧО | C15: жилые | F15: =VLOOKUP(B15,[3]Лист_1!$A:$E,5,0) -> 0 | G15: ПД | I15: да | R15: да | AD15: да | AF15: да
A16: Астана | B16: AruPark - 2 - 1 | C16: жилые | F16: =VLOOKUP(B16,[3]Лист_1!$A:$E,5,0) -> 0 | G16: ПД | I16: да | R16: да | AD16: да | AF16: да
A17: Астана | B17: AruPark - 2 - 1 - ЧО | C17: жилые | F17: =VLOOKUP(B17,[3]Лист_1!$A:$E,5,0) -> 0 | G17: ПД | I17: да | R17: да | AD17: да | AF17: да
A18: Астана | B18: AruPark 2-2 подъезд 5, 8 | C18: жилые | F18: =VLOOKUP(B18,[3]Лист_1!$A:$E,5,0) -> 0 | G18: ДДУ | L18: да | M18: да | Q18: да | S18: да | W18: да 36 | Y18: да | AD18: да
A19: Астана | B19: AruPark 2 - 2 - ЧО | C19: жилые | F19: =VLOOKUP(B19,[3]Лист_1!$A:$E,5,0) -> 0 | G19: ДДУ | L19: да | M19: да | P19: да | Q19: да | S19: да | W19: да 36 | Y19: да | AD19: да
A20: Астана | B20: AruPark - 3 | C20: жилые | F20: =VLOOKUP(B20,[3]Лист_1!$A:$E,5,0) -> 20 | G20: ДДУ | I20: да, max 530 200 тенге за 1 кв.м. | L20: да | M20: да | P20: да | Q20: да | S20: да | T20: да | W20: да 36 | Y20: да | AD20: да
A21: Астана | B21: AruPark - 3 - ЧО | C21: жилые | F21: =VLOOKUP(B21,[3]Лист_1!$A:$E,5,0) -> 8 | G21: ДДУ | L21: да | M21: да | P21: да | Q21: да | S21: да | W21: да 36 | Y21: да | AD21: да
A22: Астана | B22: Aisar - 1 | C22: жилые | F22: =VLOOKUP(B22,[3]Лист_1!$A:$E,5,0) -> 0 | G22: ПД | I22: да, max 478 000 тенге за 1 кв.м. | K22: да 1 ком.- 537000 тг 2 ком.- 459000 тг 3 ком.- 449000 тг 4 ком.- 437000 тг | N22: да, max 478 000 тенге за 1 кв.м. | O22: да, max 478 000 тенге за 1 кв.м. | R22: да | AD22: да | AF22: да
A23: Астана | B23: Aisar - 2 | C23: жилые | F23: =VLOOKUP(B23,[3]Лист_1!$A:$E,5,0) -> 3 | G23: ДДУ | L23: да | M23: да | Q23: да | S23: да | T23: да | W23: да 36 | Y23: да, max 850 000 тенге за 1 кв.м. | AA23: да, max 850 000 тенге за 1 кв.м. | AD23: да | AE23: да
A24: Астана | B24: Aisar 3 | C24: жилые | F24: =VLOOKUP(B24,[3]Лист_1!$A:$E,5,0) -> 101 | G24: ДДУ | I24: да, max 554 400 тенге за 1 кв.м. | L24: да | M24: да | P24: да | Q24: да | S24: да | T24: да | W24: да 36 | Y24: да | AD24: да
A25: Астана | B25: Aisar - 4 | C25: жилые | F25: =VLOOKUP(B25,[3]Лист_1!$A:$E,5,0) -> 183 | G25: ДДУ | L25: да | M25: да | P25: да | Q25: да | S25: да | W25: да 36 | Y25: да | AD25: да
A26: Астана | B26: Atlant - 6 | C26: жилые | F26: =VLOOKUP(B26,[3]Лист_1!$A:$E,5,0) -> 0 | G26: ПД | I26: да, 1 ком.- 850471 тг 2 ком.- 850471 тг 3 ком.- 841306 тг 4 ком.- 830036 тг 5 ком.- 890458 тг. | N26: да, 1 ком.- 850471 тг 2 ком.- 850471 тг 3 ком.- 841306 тг 4 ком.- 830036 тг 5 ком.- 890458 тг. | O26: да, 1 ком.- 850471 тг 2 ком.- 850471 тг 3 ком.- 841306 тг 4 ком.- 830036 тг 5 ком.- 890458 тг. | R26: да
A27: Астана | B27: Atlant - 6 - 2 | C27: жилые | F27: =VLOOKUP(B27,[3]Лист_1!$A:$E,5,0) -> 20 | G27: ДДУ | L27: да | M27: да | P27: да | Q27: да | W27: да 36 | Y27: да | AD27: да
A28: Астана | B28: Atlant Unique - 5 | C28: жилые | F28: =VLOOKUP(B28,[3]Лист_1!$A:$E,5,0) -> 11 | G28: ДДУ | L28: да | M28: да | P28: да | Q28: да | S28: да | W28: да 36 | Y28: да, max 1 118 750 тенге за 1 кв.м. | Z28: да, max 1 118 750 тенге за 1 кв.м. | AA28: да, max 1 118 750 тенге за 1 кв.м. | AD28: да | AE28: да
A29: Астана | B29: Arena City - 2 | C29: жилые | F29: =VLOOKUP(B29,[3]Лист_1!$A:$E,5,0) -> 0 | G29: ПД | I29: да, max 620 000 тенге за 1 кв.м. | O29: да, max 620 000 тенге за 1 кв.м. | P29: да офлайн | R29: да | W29: да 36 | AD29: да | AE29: да | AF29: да
A30: Алматы | B30: Arena City Balance - A | C30: жилые | F30: 78 | G30: ДДУ | L30: да | M30: да | Q30: да | W30: да 36 | Y30: да | AD30: да
A31: Алматы | B31: Arena City Balance - B | C31: жилые | F31: =VLOOKUP(B31,[3]Лист_1!$A:$E,5,0) -> 175 | G31: ДДУ | L31: да | M31: да | P31: да | Q31: да | S31: да | W31: да 36 | Y31: да | AD31: да
A32: Алматы | B32: Arena City Balance - B Big+ | C32: жилые | F32: 0 | G32: ДДУ | P32: да | W32: да 36
A33: Астана | B33: Arena Garden 1-1 | C33: жилые | F33: =VLOOKUP(B33,[3]Лист_1!$A:$E,5,0) -> 0 | G33: ПД | I33: да, 1 ком.- 590850 тг 2 ком.- 569790 тг 3 ком.- 525330 тг | O33: да, 1 ком.- 590850 тг 2 ком.- 569790 тг 3 ком.- 525330 тг | P33: да офлайн | R33: да | W33: да 36 | AD33: да | AE33: да | AF33: да
A34: Астана | B34: Arena Garden 1-2 | C34: жилые | F34: =VLOOKUP(B34,[3]Лист_1!$A:$E,5,0) -> 0 | G34: ДДУ | L34: да | M34: да | P34: да | Q34: да | S34: да | W34: да 36 | Y34: да, max 650 000 тенге за 1 кв.м. | Z34: да, max 650 000 тенге за 1 кв.м. | AA34: да, max 650 000 тенге за 1 кв.м. | AD34: да | AE34: да
A35: Астана | B35: Arena Towers 2 - 2 | C35: жилые | F35: =VLOOKUP(B35,[3]Лист_1!$A:$E,5,0) -> 3 | G35: ДДУ | L35: да | M35: да | P35: да | Q35: да | W35: да 36 | Y35: да | AD35: да | AE35: да
A36: Астана | B36: Auez Comfort - 1 | C36: жилые | F36: =VLOOKUP(B36,[3]Лист_1!$A:$E,5,0) -> 13 | G36: ДДУ | L36: да | M36: да | P36: да | Q36: да | S36: да | W36: да 36 | Y36: да, max 850 000 тенге за 1 кв.м. | Z36: да, max 850 000 тенге за 1 кв.м. | AA36: да, max 850 000 тенге за 1 кв.м. | AB36: да | AD36: да
A37: Астана | B37: Auez Comfort - 2 | C37: жилые | F37: =VLOOKUP(B37,[3]Лист_1!$A:$E,5,0) -> 14 | G37: ДДУ | L37: да | M37: да | P37: да | Q37: да | S37: да | W37: да 36 | Y37: да, max 850 000 тенге за 1 кв.м. | AA37: да, max 850 000 тенге за 1 кв.м. | AD37: да
A38: Астана | B38: Auez Park | C38: жилые | F38: =VLOOKUP(B38,[3]Лист_1!$A:$E,5,0) -> 86 | G38: ДДУ | L38: да | M38: да | P38: да | Q38: да | S38: да | W38: да 36 | Y38: да | AB38: да | AD38: да
A39: Астана | B39: Darmen - 1 | C39: жилые | F39: =VLOOKUP(B39,[3]Лист_1!$A:$E,5,0) -> 35 | G39: P-S | AB39: да
A40: Астана | B40: GreenLine.Verda - 1 | C40: жилые | F40: =VLOOKUP(B40,[3]Лист_1!$A:$E,5,0) -> 82 | G40: ДДУ | L40: да | M40: да | P40: да | Q40: да | W40: да 36 | Y40: да, max 1 210 300 тенге за 1 кв.м. | AA40: да, max 1 210 300 тенге за 1 кв.м. | AB40: да | AD40: да
...

Sheet Калькулятор для ОП
A1: С подтверждением дохода | F1: Отбасы Банк
B2: БЦК | C2: Алтын | D2: Фридом | E2: Халык | F2: 30/70 | H2: 50/50
A3: Стоимость недвижимости | B3: 25973880
A4: Стоимость в ипотеку | B4: =B3*1.05 -> 27272574 | C4: =B3*1.05 -> 27272574 | D4: =B3*1.05 -> 27272574 | E4: =B3*1.05 -> 27272574 | F4: =B3*1.05 -> 27272574 | H4: =B3 -> 25973880
A5: Первоначальный взнос, % | B5: 0.21 | F5: 0.3 | H5: 0.5
A6: Первоначальный взнос в тенге | B6: =B4*$B$5 -> 5727240.5 | C6: =C4*$B$5 -> 5727240.5 | D6: =D4*$B$5 -> 5727240.5 | E6: =E4*$B$5 -> 5727240.5 | F6: =F5*F4 -> 8181772.2 | H6: =H5*H4 -> 12986940
A7: Сумма Займа | B7: =B4-B6 -> 21545333 | C7: =C4-C6 -> 21545333 | D7: =D4-D6 -> 21545333 | E7: =E4-E6 -> 21545333 | F7: =F4-F6 -> 19090802 | H7: =H4-H6 -> 12986940
A8: Срок кредита | B8: 35 | C8: 35 | D8: 120 | E8: 120 | F8: ="первые "& '[2]Sheet 1'!$B$15 &" года" -> первые 3 года | G8: ="оставшиеся "& '[2]Sheet 1'!$B$16 &" лет" -> оставшиеся 9 лет | H8: ="первые "& '[2]Sheet 1'!$B$15 &" года" -> первые 3 года | I8: ="оставшиеся "& '[2]Sheet 1'!$B$16 &" лет" -> оставшиеся 9 лет
A9: Ставка вознагражд годовая | B9: =IF(B8<=12, IF(B5>=70%,'БЦК - Super ипотека'!D24, IF(B5>=50%,'БЦК - Super ипотека'!C24, IF(B5>=20%,'БЦК - Super ипотека'!B24,""))), IF(B8<=24, IF(B5>=70%,'БЦК - Super ипотека'!D25, IF(B5>=50%,'БЦК - Super ипотека'!C25, IF(B5>=20%,'БЦК - Super ипотека'!B25,""))), IF(B8<=36, IF(B5>=70%,'БЦК - Super ипотека'!D26, IF(B5>=50%,'БЦК - Super ипотека'!C26, IF(B5>=20%,'БЦК - Super ипотека'!B26,""))), IF(B8<=60, IF(B5>=70%,'БЦК - Super ипотека'!D27, IF(B5>=50%,'БЦК - Super ипотека'!C27, IF(B5>=20%,'БЦК - Super ипотека'!B27,""))), IF(B8<=120, IF(B5>=70%,'БЦК - Super ипотека'!D28, IF(B5>=50%,'БЦК - Super ипотека'!C28, IF(B5>=20%,'БЦК - Super ипотека'!B28,""))), IF(B8<=180, IF(B5>=70%,'БЦК - Super ипотека'!D29, IF(B5>=50%,'БЦК - Super ипотека'!C29, IF(B5>=20%,'БЦК - Super ипотека'!B29,""))))))))) -> 0.115 | C9: =(IF(C8<=12, IF(B5<20%,'Алтын Банк - Онай'!B24, IF(B5<30%,'Алтын Банк - Онай'!C24, IF(B5<40%,'Алтын Банк - Онай'!C24, IF(B5<50%,'Алтын Банк - Онай'!C24, IF(B5<60%,'Алтын Банк - Онай'!C24,'Алтын Банк - Онай'!C24))))), IF(C8<=24, IF(B5<20%,'Алтын Банк - Онай'!C25, IF(B5<30%,'Алтын Банк - Онай'!C25, IF(B5<40%,'Алтын Банк - Онай'!D25, IF(B5<50%,'Алтын Банк - Онай'!E25, IF(B5<60%,'Алтын Банк - Онай'!F25,'Алтын Банк - Онай'!G25))))), IF(C8<=36, IF(B5<20%,'Алтын Банк - Онай'!B26, IF(B5<30%,'Алтын Банк - Онай'!C26, IF(B5<40%,'Алтын Банк - Онай'!D26, IF(B5<50%,'Алтын Банк - Онай'!E26, IF(B5<60%,'Алтын Банк - Онай'!F26,'Алтын Банк - Онай'!G26))))), IF(C8<=60, IF(B5<20%,'Алтын Банк - Онай'!B27, IF(B5<30%,'Алтын Банк - Онай'!C27, IF(B5<40%,'Алтын Банк - Онай'!D27, IF(B5<50%,'Алтын Банк - Онай'!E27, IF(B5<60%,'Алтын Банк - Онай'!F27,'Алтын Банк - Онай'!G27))))), IF(C8<=120, IF(B5<20%,'Алтын Банк - Онай'!B28, IF(B5<30%,'Алтын Банк - Онай'!C28, IF(B5<40%,'Алтын Банк - Онай'!D28, IF(B5<50%,'Алтын Банк - Онай'!E28, IF(B5<60%,'Алтын Банк - Онай'!F28,'Алтын Банк - Онай'!G28))))), IF(C8<=180, IF(B5<20%,'Алтын Банк - Онай'!B29, IF(B5<30%,'Алтын Банк - Онай'!C29, IF(B5<40%,'Алтын Банк - Онай'!D29, IF(B5<50%,'Алтын Банк - Онай'!E29, IF(B5<60%,'Алтын Банк - Онай'!F29,'Алтын Банк - Онай'!G29))))), IF(C8<=240, IF(B5<20%,'Алтын Банк - Онай'!B30, IF(B5<30%,'Алтын Банк - Онай'!C30, IF(B5<40%,'Алтын Банк - Онай'!D30, IF(B5<50%,'Алтын Банк - Онай'!E30, IF(B5<60%,'Алтын Банк - Онай'!F30,'Алтын Банк - Онай'!G30)))))))))))))*1% -> 0.12 | D9: =(IF(D8<=12, IF(B5<30%,'ФридБанк ДДУ'!G23, IF(B5<40%,'ФридБанк ДДУ'!F23, IF(B5<50%,'ФридБанк ДДУ'!E23, IF(B5<60%,'ФридБанк ДДУ'!D23, IF(B5<70%,'ФридБанк ДДУ'!C23,'ФридБанк ДДУ'!B23))))), IF(D8<=24, IF(B5<30%,'ФридБанк ДДУ'!G24, IF(B5<40%,'ФридБанк ДДУ'!F24, IF(B5<50%,'ФридБанк ДДУ'!E24, IF(B5<60%,'ФридБанк ДДУ'!D24, IF(B5<70%,'ФридБанк ДДУ'!C24,'ФридБанк ДДУ'!B24))))), IF(D8<=36, IF(B5<30%,'ФридБанк ДДУ'!G25, IF(B5<40%,'ФридБанк ДДУ'!F25, IF(B5<50%,'ФридБанк ДДУ'!E25, IF(B5<60%,'ФридБанк ДДУ'!D25, IF(B5<70%,'ФридБанк ДДУ'!C25,'ФридБанк ДДУ'!B25))))), IF(D8<=60, IF(B5<30%,'ФридБанк ДДУ'!G26, IF(B5<40%,'ФридБанк ДДУ'!F26, IF(B5<50%,'ФридБанк ДДУ'!E26, IF(B5<60%,'ФридБанк ДДУ'!D26, IF(B5<70%,'ФридБанк ДДУ'!C26,'ФридБанк ДДУ'!B26))))), IF(D8<=120, IF(B5<30%,'ФридБанк ДДУ'!G27, IF(B5<40%,'ФридБанк ДДУ'!F27, IF(B5<50%,'ФридБанк ДДУ'!E27, IF(B5<60%,'ФридБанк ДДУ'!D27, IF(B5<70%,'ФридБанк ДДУ'!C27,'ФридБанк ДДУ'!B27))))), IF(D8<=180, IF(B5<30%,'ФридБанк ДДУ'!G28, IF(B5<40%,'ФридБанк ДДУ'!F28, IF(B5<50%,'ФридБанк ДДУ'!E28, IF(B5<60%,'ФридБанк ДДУ'!D28, IF(B5<70%,'ФридБанк ДДУ'!C28,'ФридБанк ДДУ'!B28))))), IF(D8<=240, IF(B5<30%,'ФридБанк ДДУ'!G30, IF(B5<40%,'ФридБанк ДДУ'!F29, IF(B5<50%,'ФридБанк ДДУ'!E29, IF(B5<60%,'ФридБанк ДДУ'!D29, IF(B5<70%,'ФридБанк ДДУ'!C29,'ФридБанк ДДУ'!B29)))))))))))))*1% -> 0.19 | E9: =IF(E8<=12, IF(B5>=50%,'Народный банк-Halyk ипотека'!C24,'Народный банк-Halyk ипотека'!B24), IF(E8<=24, IF(B5>=50%,'Народный банк-Halyk ипотека'!C25,'Народный банк-Halyk ипотека'!B25), IF(E8<=36, IF(B5>=50%,'Народный банк-Halyk ипотека'!C26,'Народный банк-Halyk ипотека'!B26), IF(E8<=60, IF(B5>=50%,'Народный банк-Halyk ипотека'!C27,'Народный банк-Halyk ипотека'!B27), IF(E8<=120, IF(B5>=50%,'Народный банк-Halyk ипотека'!C28,'Народный банк-Halyk ипотека'!B28), IF(E8<=180, IF(B5>=50%,'Народный банк-Halyk ипотека'!C29,'Народный банк-Halyk ипотека'!B29), IF(E8<=240, IF(B5>=50%,'Народный банк-Halyk ипотека'!C30,'Народный банк-Halyk ипотека'!B30)))))))) -> 0.17 | F9: 0.08 | G9: 0.042 | H9: 0.085 | I9: 0.042
A10: Ежемесячное погашение | B10: =IFERROR(ROUND(POWER((1+B9/12),B8)*B9/12/(POWER((1+B9/12),B8)-1)*B7,0)," ") -> 727497 | C10: =IFERROR(ROUND(POWER((1+C9/12),C8)*C9/12/(POWER((1+C9/12),C8)-1)*C7,0)," ") -> 732621 | D10: =IFERROR(ROUND(POWER((1+D9/12),D8)*D9/12/(POWER((1+D9/12),D8)-1)*D7,0)," ") -> 402192 | E10: =IFERROR(ROUND(POWER((1+E9/12),E8)*E9/12/(POWER((1+E9/12),E8)-1)*E7,0)," ") -> 374453 | F10: =F4*8%/12 + F4*20%*7%/12 -> 213635.16 | G10: =F4*0.56% + F4*20%*0.56% -> 183271.7 | H10: =H4*H9/12 -> 183981.65 | I10: =H4*0.56% -> 145453.73
A11: Переплата за весь срок | B11: =IFERROR(B10*B8-B7, " ") -> 3917061.5 | C11: =IFERROR(C10*C8-C7, " ") -> 4096401.5 | D11: =IFERROR(D10*D8-D7, " ") -> 26717707 | E11: =IFERROR(E10*E8-E7, " ") -> 23389027 | F11: =F10*'[2]Sheet 1'!$B$15*12+G10*'[2]Sheet 1'!$B$16*12-F7/2 -> 17938808 | H11: =H10*'[2]Sheet 1'!$B$15*12+I10*'[2]Sheet 1'!$B$16*12-H7/2 -> 15838872
A12: Комиссия за оформление МАХ сумма | B12: 0 | C12: 0 | D12: 30000 | E12: 0 | F12: 200000 | H12: 115000
A14: *Расчеты предоставлены приблизительно
A15: *По Отбасы Банку без учета накоплений и условий по депозиту

Sheet Калькулятор
C3: Сумма займа | E3: =#REF! -> #REF!
C4: Срок займа | E4: =#REF! -> #REF!
C5: сумма аннуитета | E5: =-PMT(E10%/12,E4,E3) -> #REF!
C6: Дата Выдачи | E6: 45047
C7: Ставки
C8: срок 1-3 | E8: =#REF! -> #REF!
C9: срок 4-5 | E9: =#REF! -> #REF!
C10: свыше 5 | E10: =#REF! -> #REF!
C11: ГЭСВ | E11: =XIRR(OFFSET(L15,0,0,E4+1,1),OFFSET(B15,0,0,E4+1,1)) -> #REF!
A14: № п/п/ № р/н | B14: Дата платежа/ Төлем күні | C14: Ежем. платеж | D14: Платеж | E14: ОД | F14: % | G14: % | H14: Остаток ОД | K14: % под новые ставки | L14: Новый еж.платеж
B15: 44953 | C15: =-E3 -> #REF! | D15: =-E3 -> #REF! | H15: =E3 -> #REF! | L15: =D15 -> #REF!
A16: 1 | B16: =DATE(YEAR(E6),MONTH(E6)+1,DAY(E6)) -> 45078 | C16: =L16 -> #REF! | D16: =E5 -> #REF! | E16: =D16-F16 -> #REF! | F16: =H15*$E$10%/12 -> #REF! | G16: =K16 -> #REF! | H16: =H15-E16 -> #REF! | J16: =$E$8 -> #REF! | K16: =H15*J16%/12 -> #REF! | L16: =E16+K16 -> #REF!
A17: 2 | B17: =DATE(YEAR(B16),MONTH(B16)+1,DAY(B16)) -> 45108 | C17: =L17 -> #REF! | D17: =D16 -> #REF! | E17: =D17-F17 -> #REF! | F17: =H16*$E$10%/12 -> #REF! | G17: =K17 -> #REF! | H17: =H16-E17 -> #REF! | J17: =$E$8 -> #REF! | K17: =H16*J17%/12 -> #REF! | L17: =E17+K17 -> #REF!
A18: 3 | B18: =DATE(YEAR(B17),MONTH(B17)+1,DAY(B17)) -> 45139 | C18: =L18 -> #REF! | D18: =D17 -> #REF! | E18: =D18-F18 -> #REF! | F18: =H17*$E$10%/12 -> #REF! | G18: =K18 -> #REF! | H18: =H17-E18 -> #REF! | J18: =$E$8 -> #REF! | K18: =H17*J18%/12 -> #REF! | L18: =E18+K18 -> #REF!
A19: 4 | B19: =DATE(YEAR(B18),MONTH(B18)+1,DAY(B18)) -> 45170 | C19: =L19 -> #REF! | D19: =D18 -> #REF! | E19: =D19-F19 -> #REF! | F19: =H18*$E$10%/12 -> #REF! | G19: =K19 -> #REF! | H19: =H18-E19 -> #REF! | J19: =$E$8 -> #REF! | K19: =H18*J19%/12 -> #REF! | L19: =E19+K19 -> #REF!
A20: 5 | B20: =DATE(YEAR(B19),MONTH(B19)+1,DAY(B19)) -> 45200 | C20: =L20 -> #REF! | D20: =D19 -> #REF! | E20: =D20-F20 -> #REF! | F20: =H19*$E$10%/12 -> #REF! | G20: =K20 -> #REF! | H20: =H19-E20 -> #REF! | J20: =$E$8 -> #REF! | K20: =H19*J20%/12 -> #REF! | L20: =E20+K20 -> #REF!
A21: 6 | B21: =DATE(YEAR(B20),MONTH(B20)+1,DAY(B20)) -> 45231 | C21: =L21 -> #REF! | D21: =D20 -> #REF! | E21: =D21-F21 -> #REF! | F21: =H20*$E$10%/12 -> #REF! | G21: =K21 -> #REF! | H21: =H20-E21 -> #REF! | J21: =$E$8 -> #REF! | K21: =H20*J21%/12 -> #REF! | L21: =E21+K21 -> #REF!
A22: 7 | B22: =DATE(YEAR(B21),MONTH(B21)+1,DAY(B21)) -> 45261 | C22: =L22 -> #REF! | D22: =D21 -> #REF! | E22: =D22-F22 -> #REF! | F22: =H21*$E$10%/12 -> #REF! | G22: =K22 -> #REF! | H22: =H21-E22 -> #REF! | J22: =$E$8 -> #REF! | K22: =H21*J22%/12 -> #REF! | L22: =E22+K22 -> #REF!
A23: 8 | B23: =DATE(YEAR(B22),MONTH(B22)+1,DAY(B22)) -> 45292 | C23: =L23 -> #REF! | D23: =D22 -> #REF! | E23: =D23-F23 -> #REF! | F23: =H22*$E$10%/12 -> #REF! | G23: =K23 -> #REF! | H23: =H22-E23 -> #REF! | J23: =$E$8 -> #REF! | K23: =H22*J23%/12 -> #REF! | L23: =E23+K23 -> #REF!
A24: 9 | B24: =DATE(YEAR(B23),MONTH(B23)+1,DAY(B23)) -> 45323 | C24: =L24 -> #REF! | D24: =D23 -> #REF! | E24: =D24-F24 -> #REF! | F24: =H23*$E$10%/12 -> #REF! | G24: =K24 -> #REF! | H24: =H23-E24 -> #REF! | J24: =$E$8 -> #REF! | K24: =H23*J24%/12 -> #REF! | L24: =E24+K24 -> #REF!
A25: 10 | B25: =DATE(YEAR(B24),MONTH(B24)+1,DAY(B24)) -> 45352 | C25: =L25 -> #REF! | D25: =D24 -> #REF! | E25: =D25-F25 -> #REF! | F25: =H24*$E$10%/12 -> #REF! | G25: =K25 -> #REF! | H25: =H24-E25 -> #REF! | J25: =$E$8 -> #REF! | K25: =H24*J25%/12 -> #REF! | L25: =E25+K25 -> #REF!
A26: 11 | B26: =DATE(YEAR(B25),MONTH(B25)+1,DAY(B25)) -> 45383 | C26: =L26 -> #REF! | D26: =D25 -> #REF! | E26: =D26-F26 -> #REF! | F26: =H25*$E$10%/12 -> #REF! | G26: =K26 -> #REF! | H26: =H25-E26 -> #REF! | J26: =$E$8 -> #REF! | K26: =H25*J26%/12 -> #REF! | L26: =E26+K26 -> #REF!
A27: 12 | B27: =DATE(YEAR(B26),MONTH(B26)+1,DAY(B26)) -> 45413 | C27: =L27 -> #REF! | D27: =D26 -> #REF! | E27: =D27-F27 -> #REF! | F27: =H26*$E$10%/12 -> #REF! | G27: =K27 -> #REF! | H27: =H26-E27 -> #REF! | J27: =$E$8 -> #REF! | K27: =H26*J27%/12 -> #REF! | L27: =E27+K27 -> #REF!
A28: 13 | B28: =DATE(YEAR(B27),MONTH(B27)+1,DAY(B27)) -> 45444 | C28: =L28 -> #REF! | D28: =D27 -> #REF! | E28: =D28-F28 -> #REF! | F28: =H27*$E$10%/12 -> #REF! | G28: =K28 -> #REF! | H28: =H27-E28 -> #REF! | J28: =$E$8 -> #REF! | K28: =H27*J28%/12 -> #REF! | L28: =E28+K28 -> #REF!
... A51: 36 | B51: =DATE(YEAR(B50),MONTH(B50)+1,DAY(B50)) -> 46143 | C51: =L51 -> #REF! | D51: =D50 -> #REF! | E51: =D51-F51 -> #REF! | F51: =H50*$E$10%/12 -> #REF! | G51: =K51 -> #REF! | H51: =H50-E51 -> #REF! | J51: =$E$8 -> #REF! | K51: =H50*J51%/12 -> #REF! | L51: =E51+K51 -> #REF!
A52: 37 | B52: =DATE(YEAR(B51),MONTH(B51)+1,DAY(B51)) -> 46174 | C52: =L52 -> #REF! | D52: =D51 -> #REF! | E52: =D52-F52 -> #REF! | F52: =H51*$E$10%/12 -> #REF! | G52: =K52 -> #REF! | H52: =H51-E52 -> #REF! | J52: =$E$9 -> #REF! | K52: =H51*J52%/12 -> #REF! | L52: =E52+K52 -> #REF!
A53: 38 | B53: =DATE(YEAR(B52),MONTH(B52)+1,DAY(B52)) -> 46204 | C53: =L53 -> #REF! | D53: =D52 -> #REF! | E53: =D53-F53 -> #REF! | F53: =H52*$E$10%/12 -> #REF! | G53: =K53 -> #REF! | H53: =H52-E53 -> #REF! | J53: =$E$9 -> #REF! | K53: =H52*J53%/12 -> #REF! | L53: =E53+K53 -> #REF!
A54: 39 | B54: =DATE(YEAR(B53),MONTH(B53)+1,DAY(B53)) -> 46235 | C54: =L54 -> #REF! | D54: =D53 -> #REF! | E54: =D54-F54 -> #REF! | F54: =H53*$E$10%/12 -> #REF! | G54: =K54 -> #REF! | H54: =H53-E54 -> #REF! | J54: =$E$9 -> #REF! | K54: =H53*J54%/12 -> #REF! | L54: =E54+K54 -> #REF!
A55: 40 | B55: =DATE(YEAR(B54),MONTH(B54)+1,DAY(B54)) -> 46266 | C55: =L55 -> #REF! | D55: =D54 -> #REF! | E55: =D55-F55 -> #REF! | F55: =H54*$E$10%/12 -> #REF! | G55: =K55 -> #REF! | H55: =H54-E55 -> #REF! | J55: =$E$9 -> #REF! | K55: =H54*J55%/12 -> #REF! | L55: =E55+K55 -> #REF!
A56: 41 | B56: =DATE(YEAR(B55),MONTH(B55)+1,DAY(B55)) -> 46296 | C56: =L56 -> #REF! | D56: =D55 -> #REF! | E56: =D56-F56 -> #REF! | F56: =H55*$E$10%/12 -> #REF! | G56: =K56 -> #REF! | H56: =H55-E56 -> #REF! | J56: =$E$9 -> #REF! | K56: =H55*J56%/12 -> #REF! | L56: =E56+K56 -> #REF!
A57: 42 | B57: =DATE(YEAR(B56),MONTH(B56)+1,DAY(B56)) -> 46327 | C57: =L57 -> #REF! | D57: =D56 -> #REF! | E57: =D57-F57 -> #REF! | F57: =H56*$E$10%/12 -> #REF! | G57: =K57 -> #REF! | H57: =H56-E57 -> #REF! | J57: =$E$9 -> #REF! | K57: =H56*J57%/12 -> #REF! | L57: =E57+K57 -> #REF!
A58: 43 | B58: =DATE(YEAR(B57),MONTH(B57)+1,DAY(B57)) -> 46357 | C58: =L58 -> #REF! | D58: =D57 -> #REF! | E58: =D58-F58 -> #REF! | F58: =H57*$E$10%/12 -> #REF! | G58: =K58 -> #REF! | H58: =H57-E58 -> #REF! | J58: =$E$9 -> #REF! | K58: =H57*J58%/12 -> #REF! | L58: =E58+K58 -> #REF!
A59: 44 | B59: =DATE(YEAR(B58),MONTH(B58)+1,DAY(B58)) -> 46388 | C59: =L59 -> #REF! | D59: =D58 -> #REF! | E59: =D59-F59 -> #REF! | F59: =H58*$E$10%/12 -> #REF! | G59: =K59 -> #REF! | H59: =H58-E59 -> #REF! | J59: =$E$9 -> #REF! | K59: =H58*J59%/12 -> #REF! | L59: =E59+K59 -> #REF!
A60: 45 | B60: =DATE(YEAR(B59),MONTH(B59)+1,DAY(B59)) -> 46419 | C60: =L60 -> #REF! | D60: =D59 -> #REF! | E60: =D60-F60 -> #REF! | F60: =H59*$E$10%/12 -> #REF! | G60: =K60 -> #REF! | H60: =H59-E60 -> #REF! | J60: =$E$9 -> #REF! | K60: =H59*J60%/12 -> #REF! | L60: =E60+K60 -> #REF!
A61: 46 | B61: =DATE(YEAR(B60),MONTH(B60)+1,DAY(B60)) -> 46447 | C61: =L61 -> #REF! | D61: =D60 -> #REF! | E61: =D61-F61 -> #REF! | F61: =H60*$E$10%/12 -> #REF! | G61: =K61 -> #REF! | H61: =H60-E61 -> #REF! | J61: =$E$9 -> #REF! | K61: =H60*J61%/12 -> #REF! | L61: =E61+K61 -> #REF!
A62: 47 | B62: =DATE(YEAR(B61),MONTH(B61)+1,DAY(B61)) -> 46478 | C62: =L62 -> #REF! | D62: =D61 -> #REF! | E62: =D62-F62 -> #REF! | F62: =H61*$E$10%/12 -> #REF! | G62: =K62 -> #REF! | H62: =H61-E62 -> #REF! | J62: =$E$9 -> #REF! | K62: =H61*J62%/12 -> #REF! | L62: =E62+K62 -> #REF!
A63: 48 | B63: =DATE(YEAR(B62),MONTH(B62)+1,DAY(B62)) -> 46508 | C63: =L63 -> #REF! | D63: =D62 -> #REF! | E63: =D63-F63 -> #REF! | F63: =H62*$E$10%/12 -> #REF! | G63: =K63 -> #REF! | H63: =H62-E63 -> #REF! | J63: =$E$9 -> #REF! | K63: =H62*J63%/12 -> #REF! | L63: =E63+K63 -> #REF!
... A75: 60 | B75: =DATE(YEAR(B74),MONTH(B74)+1,DAY(B74)) -> 46874 | C75: =L75 -> #REF! | D75: =D74 -> #REF! | E75: =D75-F75 -> #REF! | F75: =H74*$E$10%/12 -> #REF! | G75: =K75 -> #REF! | H75: =H74-E75 -> #REF! | J75: =$E$9 -> #REF! | K75: =H74*J75%/12 -> #REF! | L75: =E75+K75 -> #REF!
A76: 61 | B76: =DATE(YEAR(B75),MONTH(B75)+1,DAY(B75)) -> 46905 | C76: =L76 -> #REF! | D76: =D75 -> #REF! | E76: =D76-F76 -> #REF! | F76: =H75*$E$10%/12 -> #REF! | G76: =K76 -> #REF! | H76: =H75-E76 -> #REF! | J76: =$E$10 -> #REF! | K76: =H75*J76%/12 -> #REF! | L76: =E76+K76 -> #REF!
A77: 62 | B77: =DATE(YEAR(B76),MONTH(B76)+1,DAY(B76)) -> 46935 | C77: =L77 -> #REF! | D77: =D76 -> #REF! | E77: =D77-F77 -> #REF! | F77: =H76*$E$10%/12 -> #REF! | G77: =K77 -> #REF! | H77: =H76-E77 -> #REF! | J77: =$E$10 -> #REF! | K77: =H76*J77%/12 -> #REF! | L77: =E77+K77 -> #REF!
...

Sheet проекты Алтын
A2: Город | B2: Объекты | C2: Тип помещений | D2: Остатки на 18/08/2023 | E2: Вид основания | F2: Программа
F15: ё

Sheet БИЗНЕС ИПОТЕКА (Алтын банк)
B2: БИЗНЕС ИПОТЕКА (на офисы от Алтын Банк)
B3: Условия продукта:
B4: Срок от 1 года до 10 лет. Мах. сумма займа 200 млн. (мах стоимость помещения 400 млн.) Целевая группа: Граждане РК, жители РК с Видом на Жительства НЕЛЬЗЯ. Первоначальный взнос от 50%. Ставки вознаграждения от 0,1% до 17%. Возраст от 21 года до 65 лет. Созаемщик не участвует. Подтверждение доходов с выписками банков второго уровня на ИП (не более 5 выписок) или Kaspi pay.
B7: Кто может кредитоваться?
B8: ИП, действующее не менее 12 мес. ИП, работающие по упрощенной форме или патент.
B10: Преимущества программы:
B11: Кредитование офисов без доп. залогов на этапе строительства. Процесс оформления онлайн. Возможность оформления с косвенным подтверждением дохода. Без подтверждения ОКЭД и действий бизнеса Любая деятельность ИП (ЧСИ, нотариус не участвуют).
B16: Перечень документов:
B17: Свидетельство ИП. Декларация 910ф. за 12 мес. Патент (при наличии) Выписка со счета ИП (с интернет банкинга) Выписка с Kaspi Pay.
B20: Срок/первоначальный взнос | D20: от 50% | F20: от 60% | G20: от 70%
B21: 12 мес. | D21: 0,5 | F21: 0,1 | G21: 0.1
B22: 13-24 мес. | D22: 2 | F22: 0,5 | G22: 0.1
B23: 25-36 мес. | D23: 8,5 | F23: 5 | G23: 3
B24: 37-60 мес. | D24: 14 | F24: 11 | G24: 8.5
B25: 61-120 мес. | D25: 17 | F25: 15,5 | G25: 13.5
B29: Стоимость офиса | D29: 25000000
B30: Стоимость офиса в ипотеку | D30: =D29*1.05 -> 26250000
B31: Первоначальный взнос, % | D31: 0.5
B32: Первоначальный взнос | D32: =D30*D31 -> 13125000
B33: Сумма Займа | D33: =D30-D32 -> 13125000
B34: Ставка вознагражд годовая | D34: 0.17
B35: Срок кредита | D35: 120
B36: Ежемесячное погашение | D36: =ROUND(POWER((1+D34/12),D35)*D34/12/(POWER((1+D34/12),D35)-1)*D33,0) -> 228109
B37: Переплата за весь срок | D37: =D36*D35-D33 -> 14248080

Sheet BIG Tandau
A2: Программа «BIG Tandau» от МФО BI FINANCE | I2: Да 36/60
A3: Размер первоначального взноса | D3: Срок / Взнос | I3: Квартиры с черновой/чистовой отделкой
A4: Первоначальный взнос Черновая | D4: от 30% | I4: первоначальный взнос от 30 % | J4: ставка вознаграждения %
A5: Первоначальный взнос Чистовая | D5: от 30% | I5: 12 | J5: 8,5%
A6: Целевая группа | D6: Физические лица. Граждане РК, жители РК с Видом на Жительства до срока окончания | I6: 24 | J6: 8,5%
A7: Сумма кредита | D7: Минимум 2 млн – максимум 78 млн | I7: 36 | J7: 13%
A8: Cрок кредитования | D8: 12 мес, 24 мес, 36 мес,48 мес,60 мес | I8: 48 | J8: 13%
A9: Возраст Заемщика | D9: От 21 года до 63 лет на момент завершения срока кредита | I9: 60 | J9: 13,5%
A11: Подтверждение доходов | D11: Рассматриваются любые варианты подтверждения доходов! | I11: Да 36/60 ПВ 30%
A12: РАСХОДЫ, СВЯЗАННЫЕ С ОФОРМЛЕНИЕМ КРЕДИТА | I12: Квартиры с чистовой отделкой
A13: Комиссия за рассмотрения кредитной заявки | D13: 0 тенге | I13: первоначальный взнос от 30% | J13: ставка вознаграждения %
A14: Комиссия за предоставление займа | D14: 0 тенге | I14: 12 | J14: 8,5%
A15: Возможно доп расходы клиента: | D15: Согласие супруга 5 000 -7 000 тенге. | I15: 24 | J15: 8,5%
A16: Досрочное погашение | D16: 0 тенге | I16: 36 | J16: 13%
I17: 48 | J17: 13%
I18: 60 | J18: 13,5%
Q20: Аннуитет
Q23: Метод погашения | R23: аннуитет | T23: Расчет КДН | U23: Вводные данные | V23: Мин доход должен быть
A24: Продукт "BIG Tandau" | F24: 12 Мес | I24: 48 Мес | M24: ручной ввод | Q24: Стоимость жилья | R24: 30223000 | T24: Доход | U24: 2850389 | V24: =(U25+U29+(U30/12))/V27 -> 1772394
F25: Ежемесячное погашение | G25: =E55 -> 148852.46 | I25: Ежемесячное погашение | J25: =AA55 -> 201967.21 | M25: выпадающий список | Q25: Стоимость квартиры в ипотеку | R25: =R24*1.05 -> 31734150 | T25: Ежемесячный платеж по действующим займам | U25: 868473.05
A26: 1 транш (ежемесячные платежи) | B26: =$B$28*$B$39 -> 7868852.4 | F26: 1 транш (годовые платежи) | G26: =E46 -> 23436563 | I26: 1 транш (годовые платежи) | J26: =AA46 -> 6132142.6 | M26: расчетный результат | Q26: ПВ | R26: 0.3 | T26: Планируемый ежемесячный платеж по BIGT | U26: =R30 -> 1009748
A27: 2 транш (годовые платежи) | B27: =B37-B26 -> 14353873 | F27: Общая переплата (если 12 мес) | G27: =D47+D67 -> 2902690.8 | I27: 2 транш (годовые платежи) | J27: =AA47 -> 5594584.6 | M27: сумма ниже минимального (ПВ) | Q27: Сумма микрокредита | R27: =R25-(R25*R26) -> 22213905 | T27: КДН | U27: =(U25+U26)/U24 -> 0.65893501 | V27: 0.49
A28: Платеж из справочника | B28: =VLOOKUP('BIG Tandau'!B31,'для бигтандау'!$A$2:$F$7,MATCH('BIG Tandau'!B30,'для бигтандау'!$A$1:$F$1,0),FALSE) -> 131147.54 | I28: 3 транш (годовые платежи) | J28: =AA48 -> 5057026.7 | Q28: Срок | R28: 24
F29: 24 Мес | I29: 4 транш (годовые платежи) | J29: =AA49 -> 4519468.7 | Q29: Ставка | R29: =_xlfn.IFS('BIG Tandau'!R28='для бигтандау'!A11,'для бигтандау'!B11,'BIG Tandau'!R28='для бигтандау'!A12,'для бигтандау'!B12,'BIG Tandau'!R28='для бигтандау'!A13,'для бигтандау'!B13,'BIG Tandau'!R28='для бигтандау'!A14,'для бигтандау'!B14,'BIG Tandau'!R28='для бигтандау'!A15,'для бигтандау'!B15) -> 0.085
A30: Комнатность жилья | B30: 2-комнатная | F30: Ежемесячное погашение | G30: =L55 -> 166557.38 | I30: Общая переплата (если 48 мес) | J30: =Z50+Z103 -> 7110661.5 | M30: Расчет КДН | N30: Вводные данные | O30: Мин доход должен быть | Q30: Ежемесячный платеж | R30: =_xlfn.IFS(R28=AL43,AP45,R28=AS43,AW45,R28=AZ43,BD45,R28=BG43,BK45,R28=BN43,BR45) -> 1009748
A31: Уровень жилья | B31: стандарт | F31: 1 транш (годовые платежи) | G31: =L46 -> 12112742 | M31: Доход | N31: 2850389 | O31: =(N32+N36+(N37/12))/O34 -> 3271221.5 | Q31: Переплата | R31: =_xlfn.IFS(R28=AL43,AO57,R28=AS43,AV69,R28=AZ43,BC81,R28=BG43,BJ93,R28=BN43,BQ105) -> 2020048
A32: Отделка | B32: Черновая | F32: 2 транш (годовые платежи) | G32: =L47 -> 10825167 | M32: Ежемесячный платеж по действующим займам | N32: 868473.05 | Q32: Периодичность погашения | R32: ежемесячно
A33: Стоимость жилья | B33: 30235000 | F33: Общая переплата (если 24 мес) | G33: =K48+K79 -> 4305347.7 | I33: 60 Мес | M33: Планируемый ежемесячный платеж по BIGT (сумма ежемесячного платежа+(сумма первого платежа по годовому траншу/12)) | N33: =N36+(N37/12) -> 767137.7
A34: Стоимость квартиры в ипотеку | B34: =B33*1.05 -> 31746750 | I34: Ежемесячное погашение | J34: =AH55 -> 219672.13 | M34: КДН | N34: =(N32+N33)/N31 -> 0.57382019 | O34: 0.5
A35: Первоначальный взнос - % | B35: 0.3 | C35: мин. ПВ % | D35: =_xlfn.IFS(B32='для бигтандау'!A19,'для бигтандау'!B19,'BIG Tandau'!B32='для бигтандау'!A20,'для бигтандау'!B20) -> 0.3 | F35: 36 Мес | I35: 1 транш (годовые платежи) | J35: =AH46 -> 4808547.3
A36: Первоначальный взнос (ПВ) | B36: =B34*B35 -> 9524025 | C36: мин. ПВ | D36: =B34*D35 -> 9524025 | F36: Ежемесячное погашение | G36: =S55 -> 184262.29 | I36: 2 транш (годовые платежи) | J36: =AH47 -> 4420992.8 | M36: Ежемесячное погашение | N36: 255737.7 | O36: Необходимо менять значения в зависимости от срока, комнатности и класса
A37: Сумма займа | B37: =B34-B36 -> 22222725 | F37: 1 транш (годовые платежи) | G37: =S46 -> 8196495.4 | I37: 3 транш (годовые платежи) | J37: =AH48 -> 4033438.2 | M37: 1 транш (годовые платежи) | N37: 6136799.9
A38: ставка займа | B38: =VLOOKUP(B39, I5:J9, 2, FALSE) -> 13,5% | F38: 2 транш (годовые платежи) | G38: =S47 -> 7408931.7 | I38: 4 транш (годовые платежи) | J38: =AH49 -> 3645883.6
A39: срок займа | B39: 60 | F39: 3 транш (годовые платежи) | G39: =S48 -> 6621368.1 | I39: 5 транш (годовые платежи) | J39: =AH50 -> 3258329.1
F40: Общая переплата (если 36 мес) | G40: =R49+R91 -> 5708004.6 | I40: Общая переплата (если 60 мес) | J40: =AG51+AG115 -> 8513318.4
A43: 12 | B43: мес | H43: 24 | I43: мес | O43: 36 | P43: мес | W43: 48 | X43: мес | AD43: 60 | AE43: мес | AL43: 12 | AM43: мес | AS43: 24 | AT43: мес | AZ43: 36 | BA43: мес | BG43: 48 | BH43: мес | BN43: 60 | BO43: мес
A44: =A43/12 -> 1 | H44: =H43/12 -> 2 | O44: =O43/12 -> 3 | W44: =W43/12 -> 4 | AD44: =AD43/12 -> 5 | AL44: № | AM44: сумма на начало | AN44: ОД | AO44: вознаграждение | AP44: платеж | AQ44: сумма на конец | AS44: № | AT44: сумма на начало | AU44: ОД | AV44: вознаграждение | AW44: платеж | AX44: сумма на конец | AZ44: № | BA44: сумма на начало | BB44: ОД | BC44: вознаграждение | BD44: платеж | BE44: сумма на конец | BG44: № | BH44: сумма на начало | BI44: ОД | BJ44: вознаграждение | BK44: платеж | BL44: сумма на конец | BN44: № | BO44: сумма на начало | BP44: ОД | BQ44: вознаграждение | BR44: платеж | BS44: сумма на конец
A45: № | B45: сумма на начало | C45: ОД | D45: вознаграждение | E45: платеж | F45: сумма на конец | H45: № | I45: сумма на начало | J45: ОД | K45: вознаграждение | L45: платеж | M45: сумма на конец | O45: № | P45: сумма на начало | Q45: ОД | R45: вознаграждение | S45: платеж | T45: сумма на конец | W45: № | X45: сумма на начало | Y45: ОД | Z45: вознаграждение | AA45: платеж | AB45: сумма на конец | AD45: № | AE45: сумма на начало | AF45: ОД | AG45: вознаграждение | AH45: платеж | AI45: сумма на конец | AL45: 1 | AM45: =R27 -> 22213905 | AN45: =AP45-AO45 -> 1780143.5 | AO45: =AM45*(($R$29*30)/360) -> 157348.49 | AP45: =PMT($R$29/12,$AL$43,AM45)*-1 -> 1937492 | AQ45: =AM45-AN45 -> 20433762 | AS45: 1 | AT45: =R27 -> 22213905 | AU45: =AW45-AV45 -> 852399.55 | AV45: =AT45*(($R$29*30)/360) -> 157348.49 | AW45: =PMT($R$29/12,$AS$43,AT45)*-1 -> 1009748 | AX45: =AT45-AU45 -> 21361505 | AZ45: 1 | BA45: =R27 -> 22213905 | BB45: =BD45-BC45 -> 543889.78 | BC45: =BA45*(($R$29*30)/360) -> 157348.49 | BD45: =PMT($R$29/12,$AZ$43,BA45)*-1 -> 701238.28 | BE45: =BA45-BB45 -> 21670015 | BG45: 1 | BH45: =R27 -> 22213905 | BI45: =BK45-BJ45 -> 390186.58 | BJ45: =BH45*(($R$29*30)/360) -> 157348.49 | BK45: =PMT($R$29/12,$BG$43,BH45)*-1 -> 547535.07 | BL45: =BH45-BI45 -> 21823718 | BN45: 1 | BO45: =R27 -> 22213905 | BP45: =BR45-BQ45 -> 298403.78 | BQ45: =BO45*(($R$29*30)/360) -> 157348.49 | BR45: =PMT($R$29/12,$BN$43,BO45)*-1 -> 455752.28 | BS45: =BO45-BP45 -> 21915501
A46: 1 | B46: =B37-(B28*12) -> 20648955 | C46: =B46/A44 -> 20648955 | D46: =B46*((B38*360)/360) -> 2787608.9 | E46: =C46+D46 -> 23436563 | F46: =B46-C46 -> 0 | H46: 1 | I46: =B37-(B28*24) -> 19075184 | J46: =I46/H44 -> 9537592 | K46: =I46*((B38*360)/360) -> 2575149.8 | L46: =J46+K46 -> 12112742 | M46: =I46-J46 -> 9537592 | O46: 1 | P46: =B37-(B28*36) -> 17501414 | Q46: =P46/O44 -> 5833804.5 | R46: =P46*((B38*360)/360) -> 2362690.8 | S46: =Q46+R46 -> 8196495.4 | T46: =P46-Q46 -> 11667609 | W46: 1 | X46: =B37-(B28*48) -> 15927643 | Y46: =X46/W44 -> 3981910.8 | Z46: =X46*(($B$38*360)/360) -> 2150231.8 | AA46: =Y46+Z46 -> 6132142.6 | AB46: =X46-Y46 -> 11945732 | AD46: 1 | AE46: =B37-(B28*60) -> 14353873 | AF46: =AE46/AD44 -> 2870774.5 | AG46: =AE46*(($B$38*360)/360) -> 1937772.8 | AH46: =AF46+AG46 -> 4808547.3 | AI46: =AE46-AF46 -> 11483098 | AL46: 2 | AM46: =AQ45 -> 20433762 | AN46: =AP46-AO46 -> 1792752.8 | AO46: =AM46*(($R$29*30)/360) -> 144739.14 | AP46: =AP45 -> 1937492 | AQ46: =AM46-AN46 -> 18641009 | AS46: 2 | AT46: =AX45 -> 21361505 | AU46: =AW46-AV46 -> 858437.38 | AV46: =AT46*(($R$29*30)/360) -> 151310.66 | AW46: =AW45 -> 1009748 | AX46: =AT46-AU46 -> 20503068 | AZ46: 2 | BA46: =BE45 -> 21670015 | BB46: =BD46-BC46 -> 547742.34 | BC46: =BA46*(($R$29*30)/360) -> 153495.94 | BD46: =BD45 -> 701238.28 | BE46: =BA46-BB46 -> 21122273 | BG46: 2 | BH46: =BL45 -> 21823718 | BI46: =BK46-BJ46 -> 392950.4 | BJ46: =BH46*(($R$29*30)/360) -> 154584.67 | BK46: =BK45 -> 547535.07 | BL46: =BH46-BI46 -> 21430768 | BN46: 2 | BO46: =BS45 -> 21915501 | BP46: =BR46-BQ46 -> 300517.48 | BQ46: =BO46*(($R$29*30)/360) -> 155234.8 | BR46: =BR45 -> 455752.28 | BS46: =BO46-BP46 -> 21614984
A47: итого: | C47: =SUM(C46) -> 20648955 | D47: =SUM(D46) -> 2787608.9 | H47: 2 | I47: =M46 -> 9537592 | J47: =I46/H44 -> 9537592 | K47: =I47*((B38*360)/360) -> 1287574.9 | L47: =J47+K47 -> 10825167 | M47: =I47-J47 -> 0 | O47: 2 | P47: =T46 -> 11667609 | Q47: =P46/O44 -> 5833804.5 | R47: =P47*((B38*360)/360) -> 1575127.2 | S47: =Q47+R47 -> 7408931.7 | T47: =P47-Q47 -> 5833804.5 | W47: 2 | X47: =AB46 -> 11945732 | Y47: =X46/W44 -> 3981910.8 | Z47: =X47*(($B$38*360)/360) -> 1612673.9 | AA47: =Y47+Z47 -> 5594584.6 | AB47: =X47-Y47 -> 7963821.5 | AD47: 2 | AE47: =AI46 -> 11483098 | AF47: =AE46/AD44 -> 2870774.5 | AG47: =AE47*(($B$38*360)/360) -> 1550218.2 | AH47: =AF47+AG47 -> 4420992.8 | AI47: =AE47-AF47 -> 8612323.6 | AL47: 3 | AM47: =AQ46 -> 18641009 | AN47: =AP47-AO47 -> 1805451.5 | AO47: =AM47*(($R$29*30)/360) -> 132040.48 | AP47: =AP46 -> 1937492 | AQ47: =AM47-AN47 -> 16835557 | AS47: 3 | AT47: =AX46 -> 20503068 | AU47: =AW47-AV47 -> 864517.98 | AV47: =AT47*(($R$29*30)/360) -> 145230.07 | AW47: =AW46 -> 1009748 | AX47: =AT47-AU47 -> 19638550 | AZ47: 3 | BA47: =BE46 -> 21122273 | BB47: =BD47-BC47 -> 551622.18 | BC47: =BA47*(($R$29*30)/360) -> 149616.1 | BD47: =BD46 -> 701238.28 | BE47: =BA47-BB47 -> 20570651 | BG47: 3 | BH47: =BL46 -> 21430768 | BI47: =BK47-BJ47 -> 395733.8 | BJ47: =BH47*(($R$29*30)/360) -> 151801.27 | BK47: =BK46 -> 547535.07 | BL47: =BH47-BI47 -> 21035034 | BN47: 3 | BO47: =BS46 -> 21614984 | BP47: =BR47-BQ47 -> 302646.14 | BQ47: =BO47*(($R$29*30)/360) -> 153106.13 | BR47: =BR46 -> 455752.28 | BS47: =BO47-BP47 -> 21312338
...

Sheet Алтын Банк - Онай
A1: Оңай Алтын Банк
A4: Условия программы | D4: Срок / Взнос
A5: При полном подтверждении доходов | D5: до 20 лет / от 20%
A6: При частичном подтверждении доходов | D6: до 15 лет / от 20%
A7: Целевая группа | D7: Физические лица. Граждане РК, жители РК с Видом на Жительства до срока окончания, в случае стажа работы свыше 5 лет в КЗ то можно на мах срок займа
A8: Первоначальный взнос | D8: от 20% (При наличии дополнительного обеспечения возможно оформление кредита без первоначального взноса.)
A9: ь | D9: Минимум 1 млн – максимум 175 млн с ПД, 50 млн БПД
A10: Возраст Заемщика | D10: От 21 года до 65 лет на момент завершения срока кредита
A11: Подтверждение доходов | D11: Рассматриваются любые варианты подтверждения доходов. При ПВ от 20% возможность оформления с косвенным подтверждением дохода.
A12: РАСХОДЫ, СВЯЗАННЫЕ С ОФОРМЛЕНИЕМ КРЕДИТА
A13: Комиссия за рассмотрения кредитной заявки | D13: 0 тенге
A14: Комиссия за предоставление займа | D14: 0 тенге
A15: Возможно доп расходы клиента: | D15: Стоимость оценки 12-15 тыс. тг , регистрация Договоров Залога 3 тыс. тг (ЦОН), согласие завереное нотариусом 5 тыс. тг, страхование доп залога от 0,1% .
A16: Досрочное погашение | D16: 25 000 тенге до 12 месяцев, свыше 12 месяцев 0 тенге. Разрешается полное/частичное досрочное погашение в любое время. При частичном досрочном погашении сумма частичного погашения должна быть не менее суммы трех (очередных) ежемесячных платежей.
A17: Залогодатель | D17: Любое 3 лицо (до 70 лет должен закрыться кредит).
A18: Созаещик | D18: любое 3 лицо , не более 2 человек.
A22: Оңай (cтандарт) | I22: Алтын по акции с 01.03. по 15.04.2023г.
A23: Первоначальный взнос / срок | B23: 0% (доп.залог) | C23: 0.2 | D23: 0.3 | E23: 0.4 | F23: 0.5 | G23: 0.6 | H23: от 40% | I23: с подтв | N23: без подт-я
A24: 12 | B24: 2 | C24: 0.1 | H24: 0.1 | I24: 0.2 | J24: 0.3 | K24: 0.4 | L24: 0.5 | M24: 0.6 | N24: от 40%
A25: 13-24 | B25: 11.5 | C25: 8.5 | D25: 6.5 | E25: 4 | F25: 0.5 | G25: 0.1 | H25: 1.5 | I25: 0.1 | N25: 0.1
A26: 25-36 | B26: 15 | C26: 12 | D26: 11 | E26: 9.5 | F26: 7 | G26: 3 | H26: 7.5 | I26: 6.5 | J26: 5 | K26: 2 | L26: 0.1 | M26: 0.1 | N26: 2.5
A27: 37-60 | B27: 17.5 | C27: 16 | D27: 15 | E27: 14 | F27: 12 | G27: 10 | H27: 12 | I27: 10.5 | J27: 10 | K27: 7.5 | L27: 5 | M27: 1 | N27: 8
A28: 61-120 | B28: 18 | C28: 18 | D28: 17 | E28: 16 | F28: 15 | G28: 13 | H28: 12 | I28: 13.99 | J28: 13.5 | K28: 12 | L28: 10.5 | M28: 7.5 | N28: 12.3
A29: 121-180 | B29: 18 | C29: 18 | D29: 18 | E29: 17 | F29: 16 | G29: 15 | H29: 12 | I29: 13.99 | J29: 13.5 | K29: 13 | L29: 13 | M29: 13 | N29: 14
A30: 181-240 | B30: 18 | C30: 18 | D30: 18 | E30: 17.5 | F30: 16.5 | G30: 15.5 | H30: 14.5 | I30: 13.99 | J30: 13.5 | K30: 13 | L30: 13 | M30: 13 | N30: 14
A34: Оңай (Aкция)
A35: Первоначальный взнос / срок | B35: 0% (доп.залог) | C35: 0.2 | D35: 0.3 | E35: 0.4 | F35: 0.5 | G35: 0.6 | H35: от 40%
A36: 12 | B36: 0.1 | H36: 0.1
A37: 13-24 | B37: 7 | C37: 1.5 | D37: 0.5 | E37: 0.1 | F37: 0.1 | G37: 0.1 | H37: 0.1
A38: 25-36 | B38: 12 | C38: 8 | D38: 7 | E38: 5.5 | F38: 4 | G38: 1 | H38: 4.5
A39: 37-60 | B39: 15.5 | C39: 14 | D39: 13 | E39: 10 | F39: 8 | G39: 5 | H39: 9
A40: 61-120 | B40: 15.5 | C40: 15 | D40: 14 | E40: 12.5 | F40: 11 | G40: 9 | H40: 9.5
A41: 121-180 | B41: 16 | C41: 16 | D41: 15 | E41: 14 | F41: 13 | G41: 11 | H41: 9.5
A42: 181-240 | B42: 17 | C42: 16.5 | D42: 16 | E42: 15 | F42: 15 | G42: 13 | H42: 12.5
A44: Банк | C44: Оңай 1%
A45: доход | B45: с подтв
A46: ПВ | B46: 0% (доп.залог) | C46: 0.2 | D46: 0.3 | E46: 0.4 | F46: 0.5 | G46: 0.6
A47: 12 | B47: 0.1 | C47: 0.1
A48: 13-24 | B48: 9 | C48: 4 | D48: 3.5 | E48: 0.5 | F48: 0.1 | G48: 0.1
A49: 25-36 | B49: 12 | C49: 9 | D49: 8.5 | E49: 6 | F49: 3.5 | G49: 0.1
...

Sheet Каскад ДДУ,готов.жилье
A1: Фридом - каскадные ставки на готовое жилье и ДДУ
A3: Условия программы: | D3: Срок / Взнос
A4: При полном подтверждении доходов | D4: от 20% до 20 лет
A5: Целевая группа | D5: Физические лица. Граждане РК, жители РК с Видом на Жительства НЕЛЬЗЯ
A6: Сумма кредита | D6: Минимум 3 млн – максимум 80 млн при Каскад ДДУ, максимум 35 млн при Каскад готовое жилье
A7: Возраст Заемщика | D7: От 21 года до 63 лет на момент завершения срока кредита
A8: РАСХОДЫ, СВЯЗАННЫЕ С ОФОРМЛЕНИЕМ КРЕДИТА
A9: Комиссия за рассмотрения кредитной заявки | D9: 30 000 тенге
A10: Досрочное погашение | D10: При сокращений суммы платежа-без комисий. При сокращении срока - 1 раз 10.000 тг,последующие 20.000 тг.
A12: СТАНДАРТ
A13: Срок кредитования | B13: Размер первоначального взноса
B14: 0.2 | C14: 0.3 | D14: 0.4 | E14: 50% и более
A15: С 1 года до 3 лет (включительно) | B15: 16 | C15: 15.5 | D15: 15 | E15: 14.5
A16: С 3х лет до 5 лет (включительно) | B16: 18 | C16: 17.5 | D16: 17 | E16: 16.5
A17: На оставшийся срок (до 20 лет) | B17: 24 | C17: 24 | D17: 23 | E17: 23
A20: Стоимость квартиры | B20: 30000000 | C20: ← | D20: Менять только желтые поля!
A21: Надбавка | B21: 0.05
A22: Стоимость квартиры в ипотеку | B22: =B20*1.05 -> 31500000
A23: Первоначальный взнос - % | B23: 0.5
A24: Первоначальный взнос | B24: =B22*B23 -> 15750000
A25: Сумма Займа | B25: =B22-B24 -> 15750000
A26: Срок кредита | B26: 180 | C26: Ежемесячное погашение
A27: Ставка - с 1 до 36 месяцев | B27: =IF(B23>=0.5,14.5,IF(B23>=0.4,15,IF(B23>=0.3,15.5,16))) -> 14.5 | C27: =AVERAGE(J59:J94) -> 202246.91
A28: Ставка - с 37 до 60 месяцев | B28: =IF(B23>=0.5,16.5,IF(B23>=0.4,17,IF(B23>=0.3,17.5,18))) -> 16.5 | C28: =AVERAGE(J95:J118) -> 231096.77
A29: Ставка - с 61 до 240 месяцев | B29: =IF(B23>=0.5,23,IF(B23>=0.4,23,IF(B23>=0.3,24,24))) -> 23 | C29: =J127 -> 312111.99
A30: ГЭСВ | B30: =D51 -> 0.33996192
A31: Переплата за весь срок | B31: =C27*36+C28*24+C29*(B26-60)-B25 -> 34530651
B40: Условия компенсации | J40: Плавающие ставки | P40: Условия компенсации | X40: Плавающие ставки
B41: ПВ | C41: =B23*100 -> 50 | D41: =D48/(100-C41)% -> 31500000 | I41: 0 | J41: 1 день | K41: =K44 -> 23 | P41: ПВ | Q41: =J23*100 -> 0 | R41: =R48/(100-Q41)% -> 0 | W41: 0 | X41: 1 день | Y41: =Y44 -> 0
B42: Компенсация | C42: 10 | D42: =D41*C42% -> 3150000 | I42: 36 | J42: срок 1-3 | K42: =B27 -> 14.5 | P42: Компенсация | Q42: 10 | R42: =R41*Q42% -> 0 | W42: 36 | X42: срок 1-3 | Y42: =J27 -> 0
I43: 60 | J43: срок 4-5 | K43: =B28 -> 16.5 | W43: 60 | X43: срок 4-5 | Y43: =J28 -> 0
I44: 240 | J44: свыше 5 | K44: =B29 -> 23 | L44: 2 | W44: 240 | X44: свыше 5 | Y44: =J29 -> 0 | Z44: 2
L45: 3 | Z45: 3
L46: 4 | Z46: 4
C48: Сумма и валюта займа | D48: =B25 -> 15750000 | J48: ГЭСВ | K48: =XIRR(J58:J298,B58:B298) -> 0.25342088 | Q48: Сумма и валюта займа | R48: =J25 -> 0 | X48: ГЭСВ | Y48: =XIRR(X58:X298,P58:P298) -> #NUM!
C49: Срок займа | D49: =B26 -> 180 | J49: Общая переплата | K49: =SUM(I59:I298) -> 18669742 | Q49: Срок займа | R49: =J26 -> 0 | X49: Общая переплата | Y49: =SUM(W59:W298) -> #NUM!
C50: Ставка вознаграждения | D50: =K41 -> 23 | J50: дюрация | K50: 60 | Q50: Ставка вознаграждения | R50: =Y41 -> 0 | X50: дюрация | Y50: 60
C51: ГЭСВ | D51: =XIRR(C58:C298,B58:B298) -> 0.33996192 | J51: ГЭСВ на дюрацию | K51: =XIRR(OFFSET(L58,0,0,K50+1,1),OFFSET(B58,0,0,K50+1,1)) -> 0.24106507 | Q51: ГЭСВ | R51: =XIRR(Q58:Q298,P58:P298) -> #NUM! | X51: ГЭСВ на дюрацию | Y51: =XIRR(OFFSET(Z58,0,0,Y50+1,1),OFFSET(P58,0,0,Y50+1,1)) -> #NUM!
C52: сумма аннуитета | D52: =-PMT(K44%/12,D49,D48) -> 312111.99 | Q52: сумма аннуитета | R52: =-PMT(Y44%/12,R49,R48) -> #NUM!
C53: переплата | D53: =SUM(E59:E298) -> 24569250 | J53: остаток ОД на дюрацию | K53: =OFFSET(F58,K50,0,1,1) -> 14615557 | Q53: переплата | R53: =SUM(S59:S298) -> #NUM! | X53: остаток ОД на дюрацию | Y53: =OFFSET(T58,Y50,0,1,1) -> #NUM!
...

Sheet ФридБанк ДДУ
A1: Цифровая FFB ДДУ
A4: Условия программы: | C4: Срок / Первоначальный Взнос
A5: При полном подтверждении доходов | C5: до 15 лет / от 20%
A7: Целевая группа | C7: Физические лица. Граждане РК.
A8: Сумма кредита | C8: Минимум 3 млн – максимум 80 млн
A9: Возраст Заемщика | C9: От 21 года до 63 лет на момент завершения срока кредита
A10: Подтверждение доходов | C10: * При оформлении займа с подтверждением доходов 6 месяцев пенсионных отчислений в ЕНПФ обязательны.
A11: РАСХОДЫ, СВЯЗАННЫЕ С ОФОРМЛЕНИЕМ КРЕДИТА
A12: Комиссия за рассмотрения кредитной заявки | C12: 30 000 тенге
A13: Комиссия за предоставление займа | C13: 0 тенге
A14: Досрочное погашение | C14: При сокращений суммы платежа-без комисий. При сокращении срока - 1 раз 10.000 тг,последующие 20.000 тг.
A15: Залогодатель | C15: Любое 3 лицо (до 63 лет должен закрыться кредит).
A20: Цифровая Стандарт
A21: Срок займа в месяцах | B21: Ставки вознаграждения от первоначального взноса (% годовых)
B22: от 71 | C22: от 61 до 70 | D22: от 51 до 60 | E22: от 41 до 50 | F22: от 31 до 40 | G22: от 20 до 30
A23: 12 мес. | B23: 0.1 | C23: 0.1 | D23: 0.1 | E23: 0.1 | F23: 0.1 | G23: 0.1
A24: от 13 мес. до 24 мес. | B24: 0.1 | C24: 0.1 | D24: 2.5 | E24: 6 | F24: 8.5 | G24: 10.5
A25: от 25 мес. до 36 мес. | B25: 0.1 | C25: 5 | D25: 8.5 | E25: 11 | F25: 12.5 | G25: 14
A26: от 37 мес. до 60 мес. | B26: 6.5 | C26: 11 | D26: 13.5 | E26: 15 | F26: 16 | G26: 17
A27: от 61 мес. до 120 мес. | B27: 12.5 | C27: 15.5 | D27: 17 | E27: 18 | F27: 18.5 | G27: 19
A28: от 121 до 180 мес. | B28: 14.5 | C28: 16.5 | D28: 18 | E28: 18.5 | F28: 19 | G28: 19.5
A29: от 181 до 240 мес. | B29: 15.5 | C29: 17 | D29: 18 | E29: 19 | F29: 19.5 | G29: 20
A33: Цифровая (Aкция )
A34: Срок займа в месяцах | B34: Ставки вознаграждения от первоначального взноса (% годовых)
B35: от 70 | C35: от 60 до 70 | D35: от 50 до 60 | E35: от 40 до 50 | F35: от 30 до 40 | G35: от 20 до 30
A36: 12 мес. | B36: 0.1 | C36: 0.1 | D36: 0.1 | E36: 0.1 | F36: 0.1 | G36: 0.1
A37: 13-24 | B37: 0.1 | C37: 0.1 | D37: 0.1 | E37: 0.1 | F37: 0.1 | G37: 0.1
A38: 25-36 | B38: 0.1 | C38: 0.1 | D38: 0.1 | E38: 0.5 | F38: 3 | G38: 5
A39: 37-60 | B39: 0.1 | C39: 0.1 | D39: 4 | E39: 6.5 | F39: 8.5 | G39: 10
A40: 61-120 | B40: 2.5 | C40: 7.5 | D40: 10 | E40: 12 | F40: 13 | G40: 13.5
A41: 121-180 | B41: 6.5 | C41: 10 | D41: 12 | E41: 12.5 | F41: 13 | G41: 13.5
A42: 181-240 | B42: 8 | C42: 11 | D42: 13 | E42: 14 | F42: 15 | G42: 15.5
A46: Таблица расходов
A48: Стоимость недвижимости | B48: 55000000
A49: Стоимость квартиры в ипотеку | B49: =B48*1.05 -> 57750000
A50: Первоначальный взнос, % | B50: 0.2
A51: Первоначальный взнос | B51: =B49*B50 -> 11550000
A52: Сумма Займа | B52: =B49-B51 -> 46200000
A53: Ставка вознаграждения годовая | B53: 0.195
A54: Срок кредита | B54: 180
...

Sheet БЦК - Super  ипотека
A1: Super Ипотека БЦК
A4: Условия программы: | C4: Срок / Взнос
A5: При полном подтверждении доходов | C5: до 15 лет / от 20%
A6: При частичном подтверждении доходов | C6: до 15 лет / от 30%
A7: Целевая группа | C7: Физические лица. Граждане РК, жители РК с Видом на Жительства НЕЛЬЗЯ
A8: Первоначальный взнос | C8: от 20%
A9: Стоимость квартиры | C9: ПВ от 20%: • для городов Астана Алматы – 50 млн тенге; • для городов Шымкент, Караганда, Актау, Атырау, Актобе, Усть-Каменогорск – 45 млн тенге; • для остальных регионов – 30 млн тенге; ПВ от 30% ограничения к стоимости жилья отсутствуют
A10: Возраст Заемщика | C10: От 21 года до 68 лет на момент завершения срока кредита
A11: Подтверждение доходов | C11: Рассматриваются любые варианты подтверждения доходов!
A12: Доп.информация: | C12: Максимальный срок финансирования с финансовым анализом (полное подтв-е доходов) при первоначальном взносе от 70% составляет 120 месяцев
A13: РАСХОДЫ, СВЯЗАННЫЕ С ОФОРМЛЕНИЕМ КРЕДИТА
A14: Комиссия за рассмотрения кредитной заявки | C14: 0 тенге
A15: Комиссия за предоставление займа | C15: 0 тенге
A16: Возможно доп расходы клиента: | C16: 0 тенге
A17: Досрочное погашение | C17: 1 % от суммы до 12 месяцев, свыше 12 месяцев 0 тенге. Разрешается полное/частичное досрочное погашение в любое время.
A18: Созаещик | C18: любое 3 лицо , не более 2 человек.
A20: Объекты с ДДУ/КЖК | I20: Объекты с АВВЭ
A21: Первоначальный взнос / срок | B21: с подтверждением доходов | E21: без подтверждения доходов | I21: Первоначальный взнос / срок | J21: с подтверждением доходов | M21: без подтверждения доходов
B22: от 20% | C22: от 50% | D22: от 70% | E22: от 30% | F22: от 50% | J22: от 20% | K22: от 50% | L22: от 70% | M22: от 50%
B23: ставка | C23: ставка | D23: ставка | E23: ставка | F23: ставка | J23: ставка | K23: ставка | L23: ставка | M23: ставка
A24: 12 мес. | B24: 0.07 | C24: 0.001 | D24: 0.001 | E24: 0.07 | F24: 0.04 | I24: 12 мес. | J24: 0.09 | K24: 0.07 | L24: 0.06 | M24: 0.075
A25: 13-24 мес. | B25: 0.085 | C25: 0.075 | D25: 0.05 | E25: 0.085 | F25: 0.085 | I25: 13-24 мес. | J25: 0.1 | K25: 0.09 | L25: 0.08 | M25: 0.1
A26: 25-36 мес. | B26: 0.115 | C26: 0.105 | D26: 0.07 | E26: 0.115 | F26: 0.11 | I26: 25-36 мес. | J26: 0.13 | K26: 0.12 | L26: 0.11 | M26: 0.125
A27: 37-60 мес. | B27: 0.14 | C27: 0.135 | D27: 0.12 | E27: 0.14 | F27: 0.14 | I27: 37-180 мес. | J27: 0.155 | K27: 0.15 | L27: 15,00%* | M27: 0.155
A28: 61-120 мес. | B28: 0.14 | C28: 0.135 | D28: 0.12 | E28: 0.14 | F28: 0.14
A29: 121-180 мес. | B29: 0.1425 | C29: 0.1375 | D29: - | E29: 0.1775 | F29: 0.1425
I30: * | J30: Максимальный срок финансирования с финансовым анализом (полное подтв-е доходов) при первоначальном взносе от 70% составляет 120 месяцев
A32: Таблица расходов
A34: Стоимость недвижимости | B34: 21382560
A35: Стоимость квартиры ипотеку | B35: =B34*1.05 -> 22451688
A36: Первоначальный взнос, % | B36: 0.2
A37: Первоначальный взнос | B37: =B35*B36 -> 4490337.6
A38: Сумма Займа | B38: =B35-B37 -> 17961350
A39: Ставка вознагражд годовая | B39: 0.14
A40: Срок кредита | B40: 120
A41: Ежемесячное погашение | B41: =ROUND(POWER((1+B39/12),B40)*B39/12/(POWER((1+B39/12),B40)-1)*B38,0) -> 278879
A42: Переплата за весь срок | B42: =B41*B40-B38 -> 15504130

Sheet 50-50
A1: Стоимость жилья,тг. | B1: 7000000
A2: Возможный платеж, тг. | B2: 250000
A3: Срок накопления, лет | B3: =IF(AND(B2>=N15,B2<M15),N14,IF(AND(B2>=M15,B2<L15),M14,IF(AND(B2>=L15,B2<K15),L14,IF(AND(B2>=K15,B2<J15),K14,IF(AND(B2>=J15,B2<I15),J14,IF(AND(B2>=I15,B2<H15),I14,IF(AND(B2>=H15,B2<G15),H14,IF(AND(B2>=G15,B2<F15),G14,IF(AND(B2>=F15,B2<E15),F14,IF(AND(B2>=E15,B2<D15),E14,IF(AND(B2>=D15,B2<C15),D14,IF(AND(B2>=C15,B2<B15),C14,IF(B2>=B15,B14,"Нет вариантов"))))))))))))) -> 3
A4: Срок жилищного займа, лет | B4: =IF(B3=B14,B17,IF(B3=C14,C17,IF(B3=D14,D17,IF(B3=E14,E17,IF(B3=F14,F17,IF(B3=G14,G17,IF(B3=H14,H17,IF(B3=I14,I17,IF(B3=J14,J17,IF(B3=K14,K17,IF(B3=L14,L17,IF(B3=M14,M17,IF(B3=N14,N17))))))))))))) -> 6
A5: Ежемесячный платеж по жилищному займ, тг. | B5: =IF(B4=B17,B19,IF(B4=C17,C19,IF(B4=D17,D19,IF(B4=E17,E19,IF(B4=F17,F19,IF(B4=G17,G19,IF(B4=H17,H19,IF(B4=I17,I19,IF(B4=J17,J19,IF(B4=K17,K19,IF(B4=L17,L19,IF(B4=M17,M19,IF(B4=N17,N19))))))))))))) -> 56700
A7: При консультации клиента необходимо заполнить поля, выделенные желтым цветом: стоимость жилья (договорная сумма) и возможный платеж (ежемесячный платеж). При этом, автоматически расчитаются поля, выленным красным шрифтом: (срок накполения, срок жилищного займа, ежемесячный платеж по жилишщному займу). В ниже приведенной таблице Вы можете посмотреть более подробную информацию, в том числе ставку вознаграждения по жилищному займу.
A13: Размер ежемесячного взноса, % от договорной суммы | B13: 1.5 | C13: 1.05 | D13: 0.83 | E13: 0.66 | F13: 0.58 | G13: 0.52 | H13: 0.44 | I13: 0.38 | J13: 0.34 | K13: 0.31 | L13: 0.28 | M13: 0.26 | N13: 0.25
A14: Срок накопления, лет | B14: 3 | C14: 4 | D14: 5 | E14: 6 | F14: 7 | G14: 8 | H14: 9 | I14: 10 | J14: 11 | K14: 12 | L14: 13 | M14: 14 | N14: 15
A15: Ежемесячный взнос, тг. | B15: =B13*$B$1/100 -> 105000 | C15: =C13*$B$1/100 -> 73500 | D15: =D13*$B$1/100 -> 58100 | E15: =E13*$B$1/100 -> 46200 | F15: =F13*$B$1/100 -> 40600 | G15: =G13*$B$1/100 -> 36400 | H15: =H13*$B$1/100 -> 30800 | I15: =I13*$B$1/100 -> 26600 | ... N15: =N13*$B$1/100 -> 17500
A16: Размер ежемесячного взноса по жил.займу, % от договорной суммы | B16: 0.81 | C16: 0.7 | D16: 0.62 | E16: 0.56 | F16: 0.51 | G16: 0.46 | H16: 0.43 | I16: 0.38 | J16: 0.34 | K16: 0.31 | L16: 0.28 | M16: 0.26 | N16: 0.25
A17: Срок жилищного займа, лет | B17: 6 | C17: 7 | D17: 8 | E17: 9 | F17: 10 | G17: 11 | H17: 12 | I17: 14 | J17: 16 | K17: 18 | L17: 21 | M17: 23 | N17: 25
A18: Ставка по жилищному займу, % | B18: 0.05 | C18: 0.048 | D18: 0.045 | E18: 0.042 | F18: 0.04 | G18: 0.038 | H18: 0.037 | I18: 0.035 | J18: 0.035 | K18: 0.035 | L18: 0.035 | M18: 0.035 | N18: 0.035
A19: Ежемесячный платеж по займу, тг. | B19: =B16*$B$1/100 -> 56700 | C19: =C16*$B$1/100 -> 49000 | D19: =D16*$B$1/100 -> 43400 | E19: =E16*$B$1/100 -> 39200 | F19: =F16*$B$1/100 -> 35700 | G19: =G16*$B$1/100 -> 32200 | H19: =H16*$B$1/100 -> 30100 | I19: =I16*$B$1/100 -> 26600 | ... N19: =N16*$B$1/100 -> 17500
A21: Комисии по оформлению займа: | C21: сумма,тг
A22: Комиссия за рассмотр. кред. заявки: | C22: 5000
A23: Страхование недвижимости (0,2%) | C23: =((B1*1.1)-B1/2)*0.2% -> 8400
A24: Титульное страхование (0,2%) | C24: =((B1*1.1)-B1/2)*0.2% -> 8400 | D24: В зависимости от срока владения недвижимостью
A25: Комисия за организацию кредита (0,5% от суммы займа), макс 100 000 тг. | C25: =IF(B1*0.005>100000,100000,B1*0.005) -> 35000
A26: Комиссия за выдачу наличными (0,5% от суммы займа), макс 50 000 тг. | C26: =IF(B1*0.005>50000,50000,B1*0.005) -> 35000 | D26: Комиссия за безналичный внешний перевод займа 0,3% от суммы займа, макс - 5 000 тг. | H26: =IF(B1*0.003<5000,B1*0.003,5000) -> 5000
A27: Итого | C27: =SUM(C22:C26) -> 91800 | D27: Итого | H27: =C22+C23+C24+C25+H26 -> 61800
A29: 50-50
A30: Дата оформления пром.займа | B30: =TODAY() -> 45971
A31: Дата открытия депозита | B31: 44960 | C31: если есть депозит
A32: Начисленное вознаграждение | B32: 0
A35: Стоимость жилья,тг. | B35: 25000000 | C35: Стоимость квартиры указываем здесь
A36: Первоначальный взнос, тг. | B36: =B35/2 -> 12500000 | E36: ,
A38: Промежуточный стандартный
